---
source-updated-at: 2025-05-16T04:52:11.000Z
translation-updated-at: 2025-05-20T22:23:43.677Z
title: unstable_rethrow
description: API 关于 `unstable_rethrow` 函数的参考文档。
version: unstable
---

`unstable_rethrow` 可用于避免捕获 Next.js 在尝试处理应用程序代码中抛出的错误时产生的内部错误。

例如，调用 `notFound` 函数会抛出一个 Next.js 内部错误并渲染 [`not-found.js`](/docs/app/api-reference/file-conventions/not-found) 组件。但如果该调用位于 `try/catch` 代码块中，错误会被捕获，从而导致 `not-found.js` 无法渲染：

```tsx filename="@/app/ui/component.tsx"
import { notFound } from 'next/navigation'

export default async function Page() {
  try {
    const post = await fetch('https://.../posts/1').then((res) => {
      if (res.status === 404) notFound()
      if (!res.ok) throw new Error(res.statusText)
      return res.json()
    })
  } catch (err) {
    console.error(err)
  }
}
```

你可以使用 `unstable_rethrow` API 重新抛出内部错误，从而继续执行预期的行为：

```tsx filename="@/app/ui/component.tsx"
import { notFound, unstable_rethrow } from 'next/navigation'

export default async function Page() {
  try {
    const post = await fetch('https://.../posts/1').then((res) => {
      if (res.status === 404) notFound()
      if (!res.ok) throw new Error(res.statusText)
      return res.json()
    })
  } catch (err) {
    unstable_rethrow(err)
    console.error(err)
  }
}
```

以下 Next.js API 依赖于抛出错误，这些错误应由 Next.js 本身重新抛出并处理：

- [`notFound()`](/docs/app/api-reference/functions/not-found)
- [`redirect()`](/docs/app/building-your-application/routing/redirecting#redirect-function)
- [`permanentRedirect()`](/docs/app/building-your-application/routing/redirecting#permanentredirect-function)

如果路由段被标记为除非是静态的否则会抛出错误，动态 API 调用也会抛出不应由开发者捕获的错误。请注意，部分预渲染 (PPR) 也会影响此行为。这些 API 包括：

- [`cookies`](/docs/app/api-reference/functions/cookies)
- [`headers`](/docs/app/api-reference/functions/headers)
- [`searchParams`](/docs/app/api-reference/file-conventions/page#searchparams-optional)
- `fetch(..., { cache: 'no-store' })`
- `fetch(..., { next: { revalidate: 0 } })`

> **须知**：
>
> - 此方法应在 `catch` 代码块的顶部调用，并将错误对象作为其唯一参数传递。它也可以在 Promise 的 `.catch` 处理程序中使用。
> - 如果你确保调用会抛出错误的 API 时没有包裹在 `try/catch` 中，则无需使用 `unstable_rethrow`。
> - 任何资源清理操作（如清除间隔、定时器等）必须在调用 `unstable_rethrow` 之前或在 `finally` 代码块中完成。